Workbook

Sheet Data
A1: age | B1: sex | C1: bmi | D1: children | E1: smoker | F1: region | G1: charges | H1: north_south | I1: east_west | J1: BMI_Category
A2: 19 | B2: female | C2: 27.9 | D2: 0 | E2: yes | F2: southwest | G2: 16884.924 | H2: {=_xlfn.SWITCH(medical_cost[[#This Row],[region]],"northwest","North","northeast","North","southwest","South","southeast","South","Check")} -> South | I2: {=_xlfn.SWITCH(medical_cost[[#This Row],[region]],"northwest","West","southwest","West","northeast","East","southeast","East","Check")} -> West | J2: {=IF(NOT(ISNUMBER(medical_cost[[#This Row],[bmi]])),"Check",_xlfn.IFS(medical_cost[[#This Row],[bmi]]<20,"BMI < 20",medical_cost[[#This Row],[bmi]]<=30,"BMI 20-30",TRUE,"BMI > 30"))} -> BMI 20-30
A3: 18 | B3: male | C3: 33.77 | D3: 1 | E3: no | F3: southeast | G3: 1725.5523 | H3: {=_xlfn.SWITCH(medical_cost[[#This Row],[region]],"northwest","North","northeast","North","southwest","South","southeast","South","Check")} -> South | I3: {=_xlfn.SWITCH(medical_cost[[#This Row],[region]],"northwest","West","southwest","West","northeast","East","southeast","East","Check")} -> East | J3: {=IF(NOT(ISNUMBER(medical_cost[[#This Row],[bmi]])),"Check",_xlfn.IFS(medical_cost[[#This Row],[bmi]]<20,"BMI < 20",medical_cost[[#This Row],[bmi]]<=30,"BMI 20-30",TRUE,"BMI > 30"))} -> BMI > 30
A4: 28 | B4: male | C4: 33 | D4: 3 | E4: no | F4: southeast | G4: 4449.462 | H4: {=_xlfn.SWITCH(medical_cost[[#This Row],[region]],"northwest","North","northeast","North","southwest","South","southeast","South","Check")} -> South | I4: {=_xlfn.SWITCH(medical_cost[[#This Row],[region]],"northwest","West","southwest","West","northeast","East","southeast","East","Check")} -> East | J4: {=IF(NOT(ISNUMBER(medical_cost[[#This Row],[bmi]])),"Check",_xlfn.IFS(medical_cost[[#This Row],[bmi]]<20,"BMI < 20",medical_cost[[#This Row],[bmi]]<=30,"BMI 20-30",TRUE,"BMI > 30"))} -> BMI > 30
A5: 33 | B5: male | C5: 22.705 | D5: 0 | E5: no | F5: northwest | G5: 21984.471 | H5: {=_xlfn.SWITCH(medical_cost[[#This Row],[region]],"northwest","North","northeast","North","southwest","South","southeast","South","Check")} -> North | I5: {=_xlfn.SWITCH(medical_cost[[#This Row],[region]],"northwest","West","southwest","West","northeast","East","southeast","East","Check")} -> West | J5: {=IF(NOT(ISNUMBER(medical_cost[[#This Row],[bmi]])),"Check",_xlfn.IFS(medical_cost[[#This Row],[bmi]]<20,"BMI < 20",medical_cost[[#This Row],[bmi]]<=30,"BMI 20-30",TRUE,"BMI > 30"))} -> BMI 20-30
A6: 32 | B6: male | C6: 28.88 | D6: 0 | E6: no | F6: northwest | G6: 3866.8552 | H6: {=_xlfn.SWITCH(medical_cost[[#This Row],[region]],"northwest","North","northeast","North","southwest","South","southeast","South","Check")} -> North | I6: {=_xlfn.SWITCH(medical_cost[[#This Row],[region]],"northwest","West","southwest","West","northeast","East","southeast","East","Check")} -> West | J6: {=IF(NOT(ISNUMBER(medical_cost[[#This Row],[bmi]])),"Check",_xlfn.IFS(medical_cost[[#This Row],[bmi]]<20,"BMI < 20",medical_cost[[#This Row],[bmi]]<=30,"BMI 20-30",TRUE,"BMI > 30"))} -> BMI 20-30
A7: 31 | B7: female | C7: 25.74 | D7: 0 | E7: no | F7: southeast | G7: 3756.6216 | H7: {=_xlfn.SWITCH(medical_cost[[#This Row],[region]],"northwest","North","northeast","North","southwest","South","southeast","South","Check")} -> South | I7: {=_xlfn.SWITCH(medical_cost[[#This Row],[region]],"northwest","West","southwest","West","northeast","East","southeast","East","Check")} -> East | J7: {=IF(NOT(ISNUMBER(medical_cost[[#This Row],[bmi]])),"Check",_xlfn.IFS(medical_cost[[#This Row],[bmi]]<20,"BMI < 20",medical_cost[[#This Row],[bmi]]<=30,"BMI 20-30",TRUE,"BMI > 30"))} -> BMI 20-30
A8: 46 | B8: female | C8: 33.44 | D8: 1 | E8: no | F8: southeast | G8: 8240.5896 | H8: {=_xlfn.SWITCH(medical_cost[[#This Row],[region]],"northwest","North","northeast","North","southwest","South","southeast","South","Check")} -> South | I8: {=_xlfn.SWITCH(medical_cost[[#This Row],[region]],"northwest","West","southwest","West","northeast","East","southeast","East","Check")} -> East | J8: {=IF(NOT(ISNUMBER(medical_cost[[#This Row],[bmi]])),"Check",_xlfn.IFS(medical_cost[[#This Row],[bmi]]<20,"BMI < 20",medical_cost[[#This Row],[bmi]]<=30,"BMI 20-30",TRUE,"BMI > 30"))} -> BMI > 30
A9: 37 | B9: female | C9: 27.74 | D9: 3 | E9: no | F9: northwest | G9: 7281.5056 | H9: {=_xlfn.SWITCH(medical_cost[[#This Row],[region]],"northwest","North","northeast","North","southwest","South","southeast","South","Check")} -> North | I9: {=_xlfn.SWITCH(medical_cost[[#This Row],[region]],"northwest","West","southwest","West","northeast","East","southeast","East","Check")} -> West | J9: {=IF(NOT(ISNUMBER(medical_cost[[#This Row],[bmi]])),"Check",_xlfn.IFS(medical_cost[[#This Row],[bmi]]<20,"BMI < 20",medical_cost[[#This Row],[bmi]]<=30,"BMI 20-30",TRUE,"BMI > 30"))} -> BMI 20-30
A10: 37 | B10: male | C10: 29.83 | D10: 2 | E10: no | F10: northeast | G10: 6406.4107 | H10: {=_xlfn.SWITCH(medical_cost[[#This Row],[region]],"northwest","North","northeast","North","southwest","South","southeast","South","Check")} -> North | I10: {=_xlfn.SWITCH(medical_cost[[#This Row],[region]],"northwest","West","southwest","West","northeast","East","southeast","East","Check")} -> East | J10: {=IF(NOT(ISNUMBER(medical_cost[[#This Row],[bmi]])),"Check",_xlfn.IFS(medical_cost[[#This Row],[bmi]]<20,"BMI < 20",medical_cost[[#This Row],[bmi]]<=30,"BMI 20-30",TRUE,"BMI > 30"))} -> BMI 20-30
A11: 60 | B11: female | C11: 25.84 | D11: 0 | E11: no | F11: northwest | G11: 28923.137 | H11: {=_xlfn.SWITCH(medical_cost[[#This Row],[region]],"northwest","North","northeast","North","southwest","South","southeast","South","Check")} -> North | I11: {=_xlfn.SWITCH(medical_cost[[#This Row],[region]],"northwest","West","southwest","West","northeast","East","southeast","East","Check")} -> West | J11: {=IF(NOT(ISNUMBER(medical_cost[[#This Row],[bmi]])),"Check",_xlfn.IFS(medical_cost[[#This Row],[bmi]]<20,"BMI < 20",medical_cost[[#This Row],[bmi]]<=30,"BMI 20-30",TRUE,"BMI > 30"))} -> BMI 20-30
A12: 25 | B12: male | C12: 26.22 | D12: 0 | E12: no | F12: northeast | G12: 2721.3208 | H12: {=_xlfn.SWITCH(medical_cost[[#This Row],[region]],"northwest","North","northeast","North","southwest","South","southeast","South","Check")} -> North | I12: {=_xlfn.SWITCH(medical_cost[[#This Row],[region]],"northwest","West","southwest","West","northeast","East","southeast","East","Check")} -> East | J12: {=IF(NOT(ISNUMBER(medical_cost[[#This Row],[bmi]])),"Check",_xlfn.IFS(medical_cost[[#This Row],[bmi]]<20,"BMI < 20",medical_cost[[#This Row],[bmi]]<=30,"BMI 20-30",TRUE,"BMI > 30"))} -> BMI 20-30
A13: 62 | B13: female | C13: 26.29 | D13: 0 | E13: yes | F13: southeast | G13: 27808.725 | H13: {=_xlfn.SWITCH(medical_cost[[#This Row],[region]],"northwest","North","northeast","North","southwest","South","southeast","South","Check")} -> South | I13: {=_xlfn.SWITCH(medical_cost[[#This Row],[region]],"northwest","West","southwest","West","northeast","East","southeast","East","Check")} -> East | J13: {=IF(NOT(ISNUMBER(medical_cost[[#This Row],[bmi]])),"Check",_xlfn.IFS(medical_cost[[#This Row],[bmi]]<20,"BMI < 20",medical_cost[[#This Row],[bmi]]<=30,"BMI 20-30",TRUE,"BMI > 30"))} -> BMI 20-30
... A1339: 61 | B1339: female | C1339: 29.07 | D1339: 0 | E1339: yes | F1339: northwest | G1339: 29141.36 | H1339: {=_xlfn.SWITCH(medical_cost[[#This Row],[region]],"northwest","North","northeast","North","southwest","South","southeast","South","Check")} -> North | I1339: {=_xlfn.SWITCH(medical_cost[[#This Row],[region]],"northwest","West","southwest","West","northeast","East","southeast","East","Check")} -> West | J1339: {=IF(NOT(ISNUMBER(medical_cost[[#This Row],[bmi]])),"Check",_xlfn.IFS(medical_cost[[#This Row],[bmi]]<20,"BMI < 20",medical_cost[[#This Row],[bmi]]<=30,"BMI 20-30",TRUE,"BMI > 30"))} -> BMI 20-30

Sheet Analysis
A1: Medical Cost Analysis
A2: Excel Exercise 01
A3: Formula-Based Analysis
A5: Question 1 — North vs South Analysis
A6: Region | B6: Count | C6: Total Cost | D6: Avg BMI | F6: Check | G6: Expected | H6: Actual | I6: Status
A7: North | B7: =COUNTIF(medical_cost[north_south],Table2[[#This Row],[Region]]) -> 649 | C7: =SUMIF(medical_cost[north_south],Table2[[#This Row],[Region]],medical_cost[charges]) -> 8379380.6 | D7: =AVERAGEIF(medical_cost[north_south],Table2[[#This Row],[Region]],medical_cost[bmi]) -> 29.186664 | F7: North + South | G7: =ROWS(medical_cost[age]) -> 1338 | H7: =SUM(B7:B8) -> 1338 | I7: =IF(G7=H7,"PASS","CHECK") -> PASS
A8: South | B8: =COUNTIF(medical_cost[north_south],Table2[[#This Row],[Region]]) -> 689 | C8: =SUMIF(medical_cost[north_south],Table2[[#This Row],[Region]],medical_cost[charges]) -> 9376444.4 | D8: =AVERAGEIF(medical_cost[north_south],Table2[[#This Row],[Region]],medical_cost[bmi]) -> 32.054398 | F8: East + West | G8: =ROWS(medical_cost[age]) -> 1338 | H8: =SUM(B13:B14) -> 1338 | I8: =IF(G8=H8,"PASS","CHECK") -> PASS
F9: BMI Groups | G9: =ROWS(medical_cost[age]) -> 1338 | H9: =SUM(B19:B21) -> 1338 | I9: =IF(G9=H9,"PASS","CHECK") -> PASS
A11: Question 2 — East vs West Analysis
A12: Region | B12: Count | C12: Total Cost | D12: Avg BMI
A13: East | B13: =COUNTIF(medical_cost[east_west],Table24[[#This Row],[Region]]) -> 688 | C13: =SUMIF(medical_cost[east_west],Table24[[#This Row],[Region]],medical_cost[charges]) -> 9707358.3 | D13: =AVERAGEIF(medical_cost[east_west],Table24[[#This Row],[Region]],medical_cost[bmi]) -> 31.38633
A14: West | B14: =COUNTIF(medical_cost[east_west],Table24[[#This Row],[Region]]) -> 650 | C14: =SUMIF(medical_cost[east_west],Table24[[#This Row],[Region]],medical_cost[charges]) -> 8048466.6 | D14: =AVERAGEIF(medical_cost[east_west],Table24[[#This Row],[Region]],medical_cost[bmi]) -> 29.8982
A17: Question 3 — BMI Group Analysis
A18: BMI Group | B18: Count | C18: Avg Cost
A19: BMI < 20 | B19: =COUNTIF(medical_cost[BMI_Category],Table6[[#This Row],[BMI Group]]) -> 41 | C19: =AVERAGEIF(medical_cost[BMI_Category],Table6[[#This Row],[BMI Group]],medical_cost[charges]) -> 8838.5611
A20: BMI 20-30 | B20: =COUNTIF(medical_cost[BMI_Category],Table6[[#This Row],[BMI Group]]) -> 592 | C20: =AVERAGEIF(medical_cost[BMI_Category],Table6[[#This Row],[BMI Group]],medical_cost[charges]) -> 10849.647
A21: BMI > 30 | B21: =COUNTIF(medical_cost[BMI_Category],Table6[[#This Row],[BMI Group]]) -> 705 | C21: =AVERAGEIF(medical_cost[BMI_Category],Table6[[#This Row],[BMI Group]],medical_cost[charges]) -> 15560.926
A24: Question 4 — Average Cost by Smoker Status
A25: Smoker Status | B25: Avg Cost
A26: no | B26: =AVERAGEIF(medical_cost[smoker],Table7[[#This Row],[Smoker Status]],medical_cost[charges]) -> 8434.2683
A27: yes | B27: =AVERAGEIF(medical_cost[smoker],Table7[[#This Row],[Smoker Status]],medical_cost[charges]) -> 32050.232
A29: Question 5 — Smokers with BMI > 30
A30: Smoker Status | B30: BMI Group | C30: Avg Cost
A31: yes | B31: BMI > 30 | C31: =AVERAGEIFS(medical_cost[charges],medical_cost[smoker],A31,medical_cost[BMI_Category],B31) -> 41692.809

Sheet Alternative Methods
A1: Alternative Formula Methods
A2: Medical Cost Analysis — Excel Exercise 01 | J2: Selected Metrics Validation
A3: Multiple approaches used to validate and demonstrate alternative Excel techniques
J4: Metric | K4: Primary Analysis | L4: Method 1 | M4: Method 2 | N4: Method 3 | O4: Method 4 | P4: Method 5 | Q4: Status
A5: Method 1 | J5: North Count | K5: =Analysis!B7 -> 649 | L5: =Analysis!B7 -> 649 | M5: ='Alternative Methods'!B15 -> 649 | N5: ='Alternative Methods'!B44 -> 649 | O5: ='Alternative Methods'!B74 -> 649 | P5: ='Alternative Methods'!B103 -> 649 | Q5: =IF(AND(ROUND(L5,2)=ROUND(K5,2),ROUND(M5,2)=ROUND(K5,2),ROUND(N5,2)=ROUND(K5,2),ROUND(O5,2)=ROUND(K5,2),ROUND(P5,2)=ROUND(K5,2)),"PASS","CHECK") -> PASS
A6: Method 1 — Helper Columns (See Analysis Sheet) | J6: North Total Cost | K6: =Analysis!C7 -> 8379380.6 | L6: =Analysis!C7 -> 8379380.6 | M6: ='Alternative Methods'!C15 -> 8379380.6 | N6: ='Alternative Methods'!C44 -> 8379380.6 | O6: ='Alternative Methods'!C74 -> 8379380.6 | P6: ='Alternative Methods'!C103 -> 8379380.6 | Q6: =IF(AND(ROUND(L6,2)=ROUND(K6,2),ROUND(M6,2)=ROUND(K6,2),ROUND(N6,2)=ROUND(K6,2),ROUND(O6,2)=ROUND(K6,2),ROUND(P6,2)=ROUND(K6,2)),"PASS","CHECK") -> PASS
A7: Using derived classification columns with COUNTIF, SUMIF, AVERAGEIF and AVERAGEIFS | J7: North Avg BMI | K7: =Analysis!D7 -> 29.186664 | L7: =Analysis!D7 -> 29.186664 | M7: ='Alternative Methods'!D15 -> 29.186664 | N7: ='Alternative Methods'!D44 -> 29.186664 | O7: ='Alternative Methods'!D74 -> 29.186664 | P7: ='Alternative Methods'!D103 -> 29.186664 | Q7: =IF(AND(ROUND(L7,2)=ROUND(K7,2),ROUND(M7,2)=ROUND(K7,2),ROUND(N7,2)=ROUND(K7,2),ROUND(O7,2)=ROUND(K7,2),ROUND(P7,2)=ROUND(K7,2)),"PASS","CHECK") -> PASS
J8: East Count | K8: =Analysis!B13 -> 688 | L8: =Analysis!B13 -> 688 | M8: ='Alternative Methods'!B20 -> 688 | N8: ='Alternative Methods'!B49 -> 688 | O8: ='Alternative Methods'!B79 -> 688 | P8: ='Alternative Methods'!B108 -> 688 | Q8: =IF(AND(ROUND(L8,2)=ROUND(K8,2),ROUND(M8,2)=ROUND(K8,2),ROUND(N8,2)=ROUND(K8,2),ROUND(O8,2)=ROUND(K8,2),ROUND(P8,2)=ROUND(K8,2)),"PASS","CHECK") -> PASS
A9: Method 2 | J9: East Total Cost | K9: =Analysis!C13 -> 9707358.3 | L9: =Analysis!C13 -> 9707358.3 | M9: ='Alternative Methods'!C20 -> 9707358.3 | N9: ='Alternative Methods'!C49 -> 9707358.3 | O9: ='Alternative Methods'!C79 -> 9707358.3 | P9: ='Alternative Methods'!C108 -> 9707358.3 | Q9: =IF(AND(ROUND(L9,2)=ROUND(K9,2),ROUND(M9,2)=ROUND(K9,2),ROUND(N9,2)=ROUND(K9,2),ROUND(O9,2)=ROUND(K9,2),ROUND(P9,2)=ROUND(K9,2)),"PASS","CHECK") -> PASS
A10: Method 2 — Direct Criteria / No Helper Columns | J10: East Avg BMI | K10: =Analysis!D13 -> 31.38633 | L10: =Analysis!D13 -> 31.38633 | M10: ='Alternative Methods'!D20 -> 31.38633 | N10: ='Alternative Methods'!D49 -> 31.38633 | O10: ='Alternative Methods'!D79 -> 31.38633 | P10: ='Alternative Methods'!D108 -> 31.38633 | Q10: =IF(AND(ROUND(L10,2)=ROUND(K10,2),ROUND(M10,2)=ROUND(K10,2),ROUND(N10,2)=ROUND(K10,2),ROUND(O10,2)=ROUND(K10,2),ROUND(P10,2)=ROUND(K10,2)),"PASS","CHECK") -> PASS
A11: Direct analysis using original fields without derived classification columns | J11: BMI 20-30 Count | K11: =Analysis!B20 -> 592 | L11: =Analysis!B20 -> 592 | M11: ='Alternative Methods'!B26 -> 592 | N11: ='Alternative Methods'!B55 -> 592 | O11: ='Alternative Methods'!B85 -> 592 | P11: ='Alternative Methods'!B114 -> 592 | Q11: =IF(AND(ROUND(L11,2)=ROUND(K11,2),ROUND(M11,2)=ROUND(K11,2),ROUND(N11,2)=ROUND(K11,2),ROUND(O11,2)=ROUND(K11,2),ROUND(P11,2)=ROUND(K11,2)),"PASS","CHECK") -> PASS
J12: BMI 20-30 Avg Cost | K12: =Analysis!C20 -> 10849.647 | L12: =Analysis!C20 -> 10849.647 | M12: ='Alternative Methods'!C26 -> 10849.647 | N12: ='Alternative Methods'!C55 -> 10849.647 | O12: ='Alternative Methods'!C85 -> 10849.647 | P12: ='Alternative Methods'!C114 -> 10849.647 | Q12: =IF(AND(ROUND(L12,2)=ROUND(K12,2),ROUND(M12,2)=ROUND(K12,2),ROUND(N12,2)=ROUND(K12,2),ROUND(O12,2)=ROUND(K12,2),ROUND(P12,2)=ROUND(K12,2)),"PASS","CHECK") -> PASS
A13: Question 1 — North vs South Analysis | J13: Non-Smoker Avg Cost | K13: =Analysis!B26 -> 8434.2683 | L13: =Analysis!B26 -> 8434.2683 | M13: ='Alternative Methods'!B31 -> 8434.2683 | N13: ='Alternative Methods'!C61 -> 8434.2683 | O13: ='Alternative Methods'!C91 -> 8434.2683 | P13: ='Alternative Methods'!B120 -> 8434.2683 | Q13: =IF(AND(ROUND(L13,2)=ROUND(K13,2),ROUND(M13,2)=ROUND(K13,2),ROUND(N13,2)=ROUND(K13,2),ROUND(O13,2)=ROUND(K13,2),ROUND(P13,2)=ROUND(K13,2)),"PASS","CHECK") -> PASS
A14: Region | B14: Count | C14: Total Cost | D14: Avg BMI | J14: Smoker + BMI >30 Avg Cost | K14: =Analysis!C31 -> 41692.809 | L14: =Analysis!C31 -> 41692.809 | M14: ='Alternative Methods'!C36 -> 41692.809 | N14: ='Alternative Methods'!C66 -> 41692.809 | O14: ='Alternative Methods'!C96 -> 41692.809 | P14: ='Alternative Methods'!C125 -> 41692.809 | Q14: =IF(AND(ROUND(L14,2)=ROUND(K14,2),ROUND(M14,2)=ROUND(K14,2),ROUND(N14,2)=ROUND(K14,2),ROUND(O14,2)=ROUND(K14,2),ROUND(P14,2)=ROUND(K14,2)),"PASS","CHECK") -> PASS
A15: North | B15: =COUNTIF(medical_cost[region],"northWest")+COUNTIF(medical_cost[region],"northeast") -> 649 | C15: =SUMIF(medical_cost[region],"northWest",medical_cost[charges])+SUMIF(medical_cost[region],"northeast",medical_cost[charges]) -> 8379380.6 | D15: =(SUMIF(medical_cost[region],"northeast",medical_cost[bmi])+SUMIF(medical_cost[region],"northWest",medical_cost[bmi]))/(COUNTIF(medical_cost[region],"northeast")+COUNTIF(medical_cost[region],"northWest")) -> 29.186664
A16: South | B16: =COUNTIF(medical_cost[region],"southWest")+COUNTIF(medical_cost[region],"southeast") -> 689 | C16: =SUMIF(medical_cost[region],"southWest",medical_cost[charges])+SUMIF(medical_cost[region],"southeast",medical_cost[charges]) -> 9376444.4 | D16: =(SUMIF(medical_cost[region],"SouthWest",medical_cost[bmi])+SUMIF(medical_cost[region],"southeast",medical_cost[bmi]))/(COUNTIF(medical_cost[region],"southWest")+COUNTIF(medical_cost[region],"southeast")) -> 32.054398
A18: Question 2 — East vs West Analysis
A19: Region | B19: Count | C19: Total Cost | D19: Avg BMI
A20: East | B20: =COUNTIF(medical_cost[region],"southEast")+COUNTIF(medical_cost[region],"northeast") -> 688 | C20: =SUMIF(medical_cost[region],"southEast",medical_cost[charges])+SUMIF(medical_cost[region],"northeast",medical_cost[charges]) -> 9707358.3 | D20: =(SUMIF(medical_cost[region],"northeast",medical_cost[bmi])+SUMIF(medical_cost[region],"southeast",medical_cost[bmi]))/(COUNTIF(medical_cost[region],"northeast")+COUNTIF(medical_cost[region],"southeast")) -> 31.38633
A21: West | B21: =COUNTIF(medical_cost[region],"northWest")+COUNTIF(medical_cost[region],"southWest") -> 650 | C21: =SUMIF(medical_cost[region],"northWest",medical_cost[charges])+SUMIF(medical_cost[region],"southWest",medical_cost[charges]) -> 8048466.6 | D21: =(SUMIF(medical_cost[region],"northWest",medical_cost[bmi])+SUMIF(medical_cost[region],"southWest",medical_cost[bmi]))/(COUNTIF(medical_cost[region],"northWest")+COUNTIF(medical_cost[region],"southWest")) -> 29.8982
A23: Question 3 — BMI Group Analysis
A24: BMI Group | B24: Count | C24: Avg Cost
A25: BMI < 20 | B25: =COUNTIF(medical_cost[bmi],"<20") -> 41 | C25: =AVERAGEIF(medical_cost[bmi],"<20",medical_cost[charges]) -> 8838.5611
A26: BMI 20-30 | B26: =COUNTIFS(medical_cost[bmi],">=20",medical_cost[bmi],"<=30") -> 592 | C26: =AVERAGEIFS(medical_cost[charges],medical_cost[bmi],">=20",medical_cost[bmi],"<=30") -> 10849.647
A27: BMI > 30 | B27: =COUNTIF(medical_cost[bmi],">30") -> 705 | C27: =AVERAGEIF(medical_cost[bmi],">30",medical_cost[charges]) -> 15560.926
A29: Question 4 —Average Cost by Smoker Status
A30: Smoker Status | B30: Avg Cost
A31: no | B31: =AVERAGEIF(medical_cost[smoker],Table714[[#This Row],[Smoker Status]],medical_cost[charges]) -> 8434.2683
A32: yes | B32: =AVERAGEIF(medical_cost[smoker],Table714[[#This Row],[Smoker Status]],medical_cost[charges]) -> 32050.232
A34: Question 5 — Smokers with BMI > 30
A35: Smoker Status | B35: BMI Group | C35: Avg Cost
A36: yes | B36: BMI > 30 | C36: =AVERAGEIFS(medical_cost[charges],medical_cost[smoker],"yes",medical_cost[bmi],">30") -> 41692.809
A38: Method 3
A39: Method 3 — SUMPRODUCT
A40: Boolean and array-based analysis using SUMPRODUCT
A42: Question 1 — North vs South Analysis
A43: Region | B43: Count | C43: Total Cost | D43: Avg BMI
A44: North | B44: {=SUMPRODUCT(--(((medical_cost[region]="northWest")+(medical_cost[region]="northeast"))>0))} -> 649 | C44: {=SUMPRODUCT((((medical_cost[region]="northWest")+(medical_cost[region]="northeast"))>0)*medical_cost[charges])} -> 8379380.6 | D44: {=SUMPRODUCT((((medical_cost[region]="northWest")+(medical_cost[region]="northeast"))>0)*medical_cost[bmi])/SUMPRODUCT(--(((medical_cost[region]="northWest")+(medical_cost[region]="northeast"))>0))} -> 29.186664
A45: South | B45: {=SUMPRODUCT(--(((medical_cost[region]="southWest")+(medical_cost[region]="southeast"))>0))} -> 689 | C45: {=SUMPRODUCT((((medical_cost[region]="southWest")+(medical_cost[region]="southeast"))>0)*medical_cost[charges])} -> 9376444.4 | D45: {=SUMPRODUCT((((medical_cost[region]="southWest")+(medical_cost[region]="southeast"))>0)*medical_cost[bmi])/SUMPRODUCT(--(((medical_cost[region]="southWest")+(medical_cost[region]="southeast"))>0))} -> 32.054398
A47: Question 2 — East vs West Analysis
...

Sheet Pivot Analysis
A2: Pivot Analysis — Alternative Validation | F2: Pivot Validation
A5: Pivot 1 — North vs South | F5: Metric | G5: Analysis Result | H5: Pivot Result | I5: Status
A6: Region Group | B6: Count | C6: Avg BMI | D6: Total Cost | F6: North Count | G6: =Analysis!B7 -> 649 | H6: ='Pivot Analysis'!B7 -> 649 | I6: =IFERROR(IF(ROUND(G6,2)=ROUND(H6,2),"PASS","CHECK"),"CHECK") -> PASS
A7: North | B7: 649 | C7: 29.186664 | D7: 8379380.6 | F7: North Total Cost | G7: =Analysis!C7 -> 8379380.6 | H7: ='Pivot Analysis'!D7 -> 8379380.6 | I7: =IFERROR(IF(ROUND(G7,2)=ROUND(H7,2),"PASS","CHECK"),"CHECK") -> PASS
A8: South | B8: 689 | C8: 32.054398 | D8: 9376444.4 | F8: North Avg BMI | G8: =Analysis!D7 -> 29.186664 | H8: ='Pivot Analysis'!C7 -> 29.186664 | I8: =IFERROR(IF(ROUND(G8,2)=ROUND(H8,2),"PASS","CHECK"),"CHECK") -> PASS
A9: Grand Total | B9: 1338 | C9: 30.663397 | D9: 17755825 | F9: South Count | G9: =Analysis!B8 -> 689 | H9: ='Pivot Analysis'!B8 -> 689 | I9: =IFERROR(IF(ROUND(G9,2)=ROUND(H9,2),"PASS","CHECK"),"CHECK") -> PASS
F10: South Total Cost | G10: =Analysis!C8 -> 9376444.4 | H10: ='Pivot Analysis'!D8 -> 9376444.4 | I10: =IFERROR(IF(ROUND(G10,2)=ROUND(H10,2),"PASS","CHECK"),"CHECK") -> PASS
A11: Pivot 2 — East vs West | F11: South Avg BMI | G11: =Analysis!D8 -> 32.054398 | H11: ='Pivot Analysis'!C8 -> 32.054398 | I11: =IFERROR(IF(ROUND(G11,2)=ROUND(H11,2),"PASS","CHECK"),"CHECK") -> PASS
A12: Region Group | B12: Count | C12: Avg BMI | D12: Total Cost | F12: East Count | G12: =Analysis!B13 -> 688 | H12: ='Pivot Analysis'!B13 -> 688 | I12: =IFERROR(IF(ROUND(G12,2)=ROUND(H12,2),"PASS","CHECK"),"CHECK") -> PASS
A13: East | B13: 688 | C13: 31.38633 | D13: 9707358.3 | F13: East Total Cost | G13: =Analysis!C13 -> 9707358.3 | H13: ='Pivot Analysis'!D13 -> 9707358.3 | I13: =IFERROR(IF(ROUND(G13,2)=ROUND(H13,2),"PASS","CHECK"),"CHECK") -> PASS
A14: West | B14: 650 | C14: 29.8982 | D14: 8048466.6 | F14: East Avg BMI | G14: =Analysis!D13 -> 31.38633 | H14: ='Pivot Analysis'!C13 -> 31.38633 | I14: =IFERROR(IF(ROUND(G14,2)=ROUND(H14,2),"PASS","CHECK"),"CHECK") -> PASS
A15: Grand Total | B15: 1338 | C15: 30.663397 | D15: 17755825 | F15: West Count | G15: =Analysis!B14 -> 650 | H15: ='Pivot Analysis'!B14 -> 650 | I15: =IFERROR(IF(ROUND(G15,2)=ROUND(H15,2),"PASS","CHECK"),"CHECK") -> PASS
F16: West Total Cost | G16: =Analysis!C14 -> 8048466.6 | H16: ='Pivot Analysis'!D14 -> 8048466.6 | I16: =IFERROR(IF(ROUND(G16,2)=ROUND(H16,2),"PASS","CHECK"),"CHECK") -> PASS
A17: Pivot 3 — BMI Groups | F17: West Avg BMI | G17: =Analysis!D14 -> 29.8982 | H17: ='Pivot Analysis'!C14 -> 29.8982 | I17: =IFERROR(IF(ROUND(G17,2)=ROUND(H17,2),"PASS","CHECK"),"CHECK") -> PASS
A18: BMI Category | B18: Count | C18: Avg Cost | F18: BMI <20 Count | G18: =Analysis!B19 -> 41 | H18: ='Pivot Analysis'!B19 -> 41 | I18: =IFERROR(IF(ROUND(G18,2)=ROUND(H18,2),"PASS","CHECK"),"CHECK") -> PASS
A19: BMI < 20 | B19: 41 | C19: 8838.5611 | F19: BMI <20 Avg Cost | G19: =Analysis!C19 -> 8838.5611 | H19: ='Pivot Analysis'!C19 -> 8838.5611 | I19: =IFERROR(IF(ROUND(G19,2)=ROUND(H19,2),"PASS","CHECK"),"CHECK") -> PASS
A20: BMI 20-30 | B20: 592 | C20: 10849.647 | F20: BMI 20-30 Count | G20: =Analysis!B20 -> 592 | H20: ='Pivot Analysis'!B20 -> 592 | I20: =IFERROR(IF(ROUND(G20,2)=ROUND(H20,2),"PASS","CHECK"),"CHECK") -> PASS
A21: BMI > 30 | B21: 705 | C21: 15560.926 | F21: BMI 20-30 Avg Cost | G21: =Analysis!C20 -> 10849.647 | H21: ='Pivot Analysis'!C20 -> 10849.647 | I21: =IFERROR(IF(ROUND(G21,2)=ROUND(H21,2),"PASS","CHECK"),"CHECK") -> PASS
A22: Grand Total | B22: 1338 | C22: 13270.422 | F22: BMI >30 Count | G22: =Analysis!B21 -> 705 | H22: ='Pivot Analysis'!B21 -> 705 | I22: =IFERROR(IF(ROUND(G22,2)=ROUND(H22,2),"PASS","CHECK"),"CHECK") -> PASS
F23: BMI >30 Avg Cost | G23: =Analysis!C21 -> 15560.926 | H23: ='Pivot Analysis'!C21 -> 15560.926 | I23: =IFERROR(IF(ROUND(G23,2)=ROUND(H23,2),"PASS","CHECK"),"CHECK") -> PASS
A24: Pivot 4 — Average Cost by Smoker Status | F24: Non-Smoker Avg Cost | G24: =Analysis!B26 -> 8434.2683 | H24: ='Pivot Analysis'!C26 -> 8434.2683 | I24: =IFERROR(IF(ROUND(G24,2)=ROUND(H24,2),"PASS","CHECK"),"CHECK") -> PASS
A25: status | B25: Count | C25: Avg Cost | F25: Smoker + BMI >30 Avg Cost | G25: =Analysis!C31 -> 41692.809 | H25: ='Pivot Analysis'!B33 -> 41692.809 | I25: =IFERROR(IF(ROUND(G25,2)=ROUND(H25,2),"PASS","CHECK"),"CHECK") -> PASS
A26: no | B26: 1064 | C26: 8434.2683
A27: yes | B27: 274 | C27: 32050.232
A28: Grand Total | B28: 1338 | C28: 13270.422
A30: smoker | B30: yes
A31: Pivot 5 — Smokers with BMI > 30
A32: Row Labels | B32: Avg Cost
A33: BMI > 30 | B33: 41692.809
A34: Grand Total | B34: 41692.809

Sheet Documentation
A1: Medical Cost Analysis
A2: Excel Exercise 01
A4: Project Overview
A5: Project Name | B5: Medical Cost Analysis
A6: Project Type | B6: Excel Data Analysis Project
A7: Dataset | B7: Medical Cost Dataset
A8: Tool | B8: Microsoft Excel
A9: Main Analysis | B9: Formula-based analysis
A10: Other Methods | B10: SUMPRODUCT, FILTER, LET and PivotTables
A11: Status | B11: Completed
A13: Project Objective
A14: The goal of this project was to analyze the medical cost dataset using Excel formulas. I grouped the data by region and BMI, calculated the required counts, totals and averages, and then checked the results using other Excel methods and PivotTables.
A18: Dataset Summary
A19: Metric | B19: Value | C19: Note
A20: Total Records | B20: 1338 | C20: Number of rows in the dataset
A21: Source Columns | B21: 7 | C21: Original columns
A22: Derived Columns | B22: 3 | C22: Columns created for the analysis
A23: Total Columns | B23: 10 | C23: Source + derived columns
A24: Missing Values | B24: 0 | C24: No missing values found
A25: Region Categories | B25: 4 | C25: northwest, northeast, southwest, southeast
A26: Smoker Categories | B26: 2 | C26: yes, no
A27: Sex Categories | B27: 2 | C27: female, male
A29: Dataset Structure
A30: Field | B30: Type | C30: Role
A31: age | B31: Numeric | C31: Source
A32: sex | B32: Categorical | C32: Source
A33: bmi | B33: Numeric | C33: Source
A34: children | B34: Numeric | C34: Source
A35: smoker | B35: Categorical | C35: Source
A36: region | B36: Categorical | C36: Source
A37: charges | B37: Numeric | C37: Source
A38: north_south | B38: Categorical | C38: Created
A39: east_west | B39: Categorical | C39: Created
A40: BMI_Category | B40: Categorical | C40: Created
A42: Business Rules
A43: Category | B43: Rule | C43: Result
A44: North / South | B44: northwest or northeast | C44: North
A45: North / South | B45: southwest or southeast | C45: South
A46: East / West | B46: northeast or southeast | C46: East
A47: East / West | B47: northwest or southwest | C47: West
...
